Workbook

Sheet Candidatos
A1: N° | B1: MES | C1: EV IN - EX | D1: Reclutador/a | E1: Nombre del Candidato/a | F1: Origen del Candidato/a | G1: Familia del Cargo | H1: Nombre del Cargo | I1: Ubicación del cargo | J1: Unidad | K1: Requiere Referencias | L1: CECO | M1: Adjuntar CV | N1: Adjuntar Descriptor de Cargo | O1: Aspectos a indagar (funciones del cargo, si es confidencial para el candidato, énfasis en alguna competencia, indagar en liderazgo, etc) | P1: Referencias (solo para externos) | Q1: Fecha de petición | R1: Fecha entrevista | S1: Fecha de envío informe | T1: Tiempo de respuesta (días hábiles) | U1: Categoría del evaluado
A2: 1 | B2: abril 25 | C2: interna | D2: Daniela Contreras | E2: Jorge Alvarado Uribe | F2: Interno | G2: Profesional B C | H2: Coordinador Servicios Generales | I2: Planta Magallanes | J2: Industrial | K2: No | N2: DC_Coordinador_Servicios_Generales.pdf | O2: Énfasis en orientación a resultados y trabajo colaborativo. | Q2: 45772 | R2: 45779 | S2: 45785 | T2: =NETWORKDAYS(R2,S2)-1 | U2: Recomendado con observaciones
A3: 2 | B3: abril 25 | C3: externa | D3: Daniela Contreras | E3: Manuel González Cárcamo | F3: Externo | G3: Profesional A | H3: Líder Desarrollo Producción | I3: Oficina Central | J3: Corporativo | K3: Sí | L3: A170010311 | M3: CV_Manuel_González.pdf | N3: DC_Líder_Desarrollo_Producción.pdf | O3: Indagar en liderazgo de equipos y gestión del cambio. Proceso confidencial para el candidato. | P3: Referencias favorables | Q3: 45758 | R3: 45763 | S3: 45765 | T3: =NETWORKDAYS(R3,S3)-1 | U3: Recomendado
A4: 3 | B4: abril 25 | C4: interna | D4: Carolina Muñoz | E4: Catalina Sepúlveda Alvarado | F4: Interno | G4: Técnico B C | H4: Monitor Producción | I4: Planta Calbuco | J4: Industrial | K4: No | N4: DC_Monitor_Producción.pdf | O4: Indagar en disposición a turnos rotativos. | Q4: 45770 | R4: 45776 | S4: 45778 | T4: =NETWORKDAYS(R4,S4)-1 | U4: Recomendado
A5: 4 | B5: abril 25 | C5: interna | D5: Daniela Contreras | E5: Héctor Cárcamo Pizarro | F5: Interno | G5: Jefatura | H5: Jefe de Centro | I5: AM Chonchi | J5: Producción AM | K5: No | N5: DC_Jefe_de_Centro.pdf | O5: Evaluar estilo de liderazgo y manejo de indicadores. | Q5: 45756 | R5: 45763 | S5: 45768 | T5: =NETWORKDAYS(R5,S5)-1 | U5: No recomendado
A6: 5 | B6: abril 25 | C6: interna | D6: Fernanda Rojas | E6: Pedro Mansilla Contreras | F6: Interno | G6: Jefatura | H6: Jefe Área Piscicultura | I6: Codihue | J6: Producción AD | K6: No | N6: DC_Jefe_Área_Piscicultura.pdf | O6: Indagar en liderazgo, planificación y gestión de personas. Proceso confidencial. | Q6: 45761 | R6: 45768 | S6: 45770 | T6: =NETWORKDAYS(R6,S6)-1 | U6: Recomendado
A7: 6 | B7: abril 25 | C7: interna | D7: Daniela Contreras | E7: Claudio Araya Uribe | F7: Interno | G7: Supervisor B | H7: Supervisor Planta | I7: Planta Cailin | J7: Industrial | K7: No | N7: DC_Supervisor_Planta.pdf | O7: Énfasis en comunicación efectiva y toma de decisiones bajo presión. | Q7: 45757 | R7: 45765 | S7: 45771 | T7: =NETWORKDAYS(R7,S7)-1 | U7: Recomendado con observaciones
A8: 7 | B8: abril 25 | C8: interna | D8: Fernanda Rojas | E8: Camila Sepúlveda Navarro | F8: Interno | G8: Técnico A | H8: Técnico Eléctrico | I8: Planta Magallanes | J8: Industrial | K8: No | N8: DC_Técnico_Eléctrico.pdf | O8: Énfasis en disposición a sistema de turnos 7x7 en centro remoto. | Q8: 45775 | R8: 45783 | S8: 45785 | T8: =NETWORKDAYS(R8,S8)-1 | U8: Recomendado
A9: 8 | B9: abril 25 | C9: interna | D9: Macarena Vidal | E9: Jorge Uribe Rojas | F9: Interno | G9: Supervisor B | H9: Supervisor Centro de Cultivo | I9: AM Chonchi | J9: Producción AM | K9: No | N9: DC_Supervisor_Centro_de_Cultivo.pdf | O9: Énfasis en comunicación efectiva y toma de decisiones bajo presión. | Q9: 45758 | R9: 45765 | S9: 45771 | T9: =NETWORKDAYS(R9,S9)-1 | U9: Recomendado
A10: 9 | B10: mayo 25 | C10: interna | D10: Daniela Contreras | E10: Víctor Pérez Flores | F10: Interno | G10: Supervisor B | H10: Supervisor Planta | I10: Planta Magallanes | J10: Industrial | K10: No | N10: DC_Supervisor_Planta.pdf | O10: Indagar en liderazgo de equipos operativos y manejo de conflictos. | Q10: 45789 | R10: 45791 | S10: 45793 | T10: =NETWORKDAYS(R10,S10)-1 | U10: Recomendado con observaciones
A11: 10 | B11: mayo 25 | C11: externa | D11: Javiera Soto | E11: Claudio Soto Cheuquepil | F11: Externo | G11: Supervisor B | H11: Supervisor Planta | I11: Planta Magallanes | J11: Industrial | K11: Sí | L11: A170020704 | M11: CV_Claudio_Soto.pdf | N11: DC_Supervisor_Planta.pdf | O11: Énfasis en comunicación efectiva y toma de decisiones bajo presión. | P11: 1 referencia con observaciones | Q11: 45785 | R11: 45789 | S11: 45792 | T11: =NETWORKDAYS(R11,S11)-1 | U11: Recomendado
A12: 11 | B12: mayo 25 | C12: interna | D12: Carolina Muñoz | E12: Víctor Martínez Ruiz | F12: Interno | G12: Profesional B C | H12: Analista de Control de Gestión | I12: Oficina Central | J12: Corporativo | K12: No | L12: A170010310 | N12: DC_Analista_de_Control_de_Gestión.pdf | O12: Indagar en capacidad analítica y manejo de herramientas digitales. | Q12: 45782 | R12: 45790 | S12: 45793 | T12: =NETWORKDAYS(R12,S12)-1 | U12: Recomendado
A13: 12 | B13: mayo 25 | C13: interna | D13: Carolina Muñoz | E13: Diego Vargas Álvarez | F13: Interno | G13: Profesional B C | H13: Prevencionista de Riesgos | I13: Planta Calbuco | J13: Industrial | K13: No | N13: DC_Prevencionista_de_Riesgos.pdf | O13: Énfasis en orientación a resultados y trabajo colaborativo. | Q13: 45782 | R13: 45790 | S13: 45796 | T13: =NETWORKDAYS(R13,S13)-1 | U13: Recomendado
A14: 13 | B14: mayo 25 | C14: externa | D14: Javiera Soto | E14: Soledad Muñoz Muñoz | F14: Externo | G14: Técnico A | H14: Técnico Mantención Senior | I14: AM Melinka | J14: Producción AM | K14: No | L14: A170040209 | M14: CV_Soledad_Muñoz.pdf | N14: DC_Técnico_Mantención_Senior.pdf | O14: Indagar en resolución de problemas técnicos y autonomía. | Q14: 45793 | R14: 45799 | S14: 45804 | T14: =NETWORKDAYS(R14,S14)-1 | U14: Recomendado
A15: 14 | B15: mayo 25 | C15: interna | D15: Carolina Muñoz | E15: José Gallardo Mansilla | F15: Interno | G15: Supervisor B | H15: Supervisor Centro de Cultivo | I15: AM Chonchi | J15: Producción AM | K15: No | L15: A170040510 | N15: DC_Supervisor_Centro_de_Cultivo.pdf | O15: Énfasis en comunicación efectiva y toma de decisiones bajo presión. | Q15: 45789 | R15: 45796 | S15: 45799 | T15: =NETWORKDAYS(R15,S15)-1 | U15: Recomendado
A16: 15 | B16: mayo 25 | C16: interna | D16: Fernanda Rojas | E16: Camila Sánchez López | F16: Interno | G16: Profesional A | H16: Jefe de Proyectos TI | I16: Oficina Central | J16: Corporativo | K16: No | N16: DC_Jefe_de_Proyectos_TI.pdf | O16: Indagar en liderazgo de equipos y gestión del cambio. Proceso confidencial para el candidato. | Q16: 45799 | R16: 45803 | S16: 45805 | T16: =NETWORKDAYS(R16,S16)-1 | U16: Recomendado con observaciones
A17: 16 | B17: mayo 25 | C17: interna | D17: Javiera Soto | E17: Lorena Ruiz Álvarez | F17: Interno | G17: Profesional B C | H17: Prevencionista de Riesgos | I17: AM Melinka | J17: Producción AM | K17: No | N17: DC_Prevencionista_de_Riesgos.pdf | O17: Indagar en capacidad analítica y manejo de herramientas digitales. | Q17: 45790 | R17: 45796 | S17: 45798 | T17: =NETWORKDAYS(R17,S17)-1 | U17: Recomendado
A18: 17 | B18: mayo 25 | C18: interna | D18: Fernanda Rojas | E18: Ximena Sánchez Silva | F18: Interno | G18: Supervisor B | H18: Supervisor Centro de Cultivo | I18: AM Chonchi | J18: Producción AM | K18: No | N18: DC_Supervisor_Centro_de_Cultivo.pdf | O18: Indagar en liderazgo de equipos operativos y manejo de conflictos. | Q18: 45796 | R18: 45800 | S18: 45806 | T18: =NETWORKDAYS(R18,S18)-1 | U18: Recomendado
A19: 18 | B19: junio 25 | C19: interna | D19: Macarena Vidal | E19: Jorge Ruiz Rodríguez | F19: Interno | G19: Profesional A | H19: Líder Desarrollo Producción | I19: Oficina Central | J19: Corporativo | K19: No | N19: DC_Líder_Desarrollo_Producción.pdf | O19: Indagar en liderazgo de equipos y gestión del cambio. Proceso confidencial para el candidato. | Q19: 45820 | R19: 45825 | S19: 45827 | T19: =NETWORKDAYS(R19,S19)-1 | U19: Recomendado
A20: 19 | B20: junio 25 | C20: interna | D20: Javiera Soto | E20: Matías Alvarado Espinoza | F20: Interno | G20: Profesional B C | H20: Coordinador Servicios Generales | I20: Planta Calbuco | J20: Industrial | K20: No | N20: DC_Coordinador_Servicios_Generales.pdf | O20: Énfasis en orientación a resultados y trabajo colaborativo. | Q20: 45831 | R20: 45839 | S20: 45841 | T20: =NETWORKDAYS(R20,S20)-1 | U20: Recomendado
A21: 20 | B21: junio 25 | C21: externa | D21: Javiera Soto | E21: Soledad Rodríguez Contreras | F21: Externo | G21: Técnico A | H21: Técnico Eléctrico | I21: Planta Magallanes | J21: Industrial | K21: No | L21: A170020709 | M21: CV_Soledad_Rodríguez.pdf | N21: DC_Técnico_Eléctrico.pdf | O21: Énfasis en disposición a sistema de turnos 7x7 en centro remoto. | Q21: 45819 | R21: 45825 | S21: 45828 | T21: =NETWORKDAYS(R21,S21)-1 | U21: Recomendado con observaciones
A22: 21 | B22: junio 25 | C22: interna | D22: Macarena Vidal | E22: Karen Álvarez González | F22: Interno | G22: Profesional B C | H22: Prevencionista de Riesgos | I22: Pargua PA | J22: Otros Producción | K22: No | L22: A170030404 | N22: DC_Prevencionista_de_Riesgos.pdf | O22: Validar tolerancia a la presión y organización de tareas. | Q22: 45810 | R22: 45814 | S22: 45817 | T22: =NETWORKDAYS(R22,S22)-1 | U22: Recomendado
A23: 22 | B23: junio 25 | C23: interna | D23: Carolina Muñoz | E23: Héctor Rojas Pizarro | F23: Interno | G23: Técnico B C | H23: Técnico Laboratorio | I23: Piscicultura Rupanco | J23: Producción AD | K23: No | N23: DC_Técnico_Laboratorio.pdf | O23: Validar atención al detalle y cumplimiento de protocolos. | Q23: 45817 | R23: 45825 | S23: 45827 | T23: =NETWORKDAYS(R23,S23)-1 | U23: Recomendado
A24: 23 | B24: junio 25 | C24: interna | D24: Carolina Muñoz | E24: Nicolás Díaz Vásquez | F24: Interno | G24: Técnico B C | H24: Técnico Laboratorio | I24: Piscicultura Rupanco | J24: Producción AD | K24: No | N24: DC_Técnico_Laboratorio.pdf | O24: Indagar en disposición a turnos rotativos. | Q24: 45818 | R24: 45824 | S24: 45826 | T24: =NETWORKDAYS(R24,S24)-1 | U24: Recomendado con observaciones
A25: 24 | B25: junio 25 | C25: interna | D25: Fernanda Rojas | E25: Paulina López Uribe | F25: Interno | G25: Técnico A | H25: Técnico Eléctrico | I25: Pargua PA | J25: Otros Producción | K25: No | L25: A170030402 | N25: DC_Técnico_Eléctrico.pdf | O25: Énfasis en disposición a sistema de turnos 7x7 en centro remoto. | Q25: 45814 | R25: 45824 | S25: 45825 | T25: =NETWORKDAYS(R25,S25)-1 | U25: Recomendado
A26: 25 | B26: junio 25 | C26: externa | D26: Fernanda Rojas | E26: Nicolás Álvarez Castro | F26: Externo | G26: Jefatura | H26: Jefe de Turno | I26: Planta Calbuco | J26: Industrial | K26: Sí | L26: A170021107 | M26: CV_Nicolás_Álvarez.pdf | N26: DC_Jefe_de_Turno.pdf | O26: Evaluar estilo de liderazgo y manejo de indicadores. | P26: 2 referencias favorables | Q26: 45817 | R26: 45824 | S26: 45827 | T26: =NETWORKDAYS(R26,S26)-1 | U26: Recomendado
A27: 26 | B27: julio 25 | C27: interna | D27: Macarena Vidal | E27: Cristián Muñoz Muñoz | F27: Interno | G27: Profesional A | H27: Líder Desarrollo Producción | I27: Oficina Central | J27: Corporativo | K27: No | L27: A170010308 | N27: DC_Líder_Desarrollo_Producción.pdf | O27: Indagar en liderazgo de equipos y gestión del cambio. Proceso confidencial para el candidato. | Q27: 45852 | R27: 45856 | S27: 45860 | T27: =NETWORKDAYS(R27,S27)-1 | U27: Recomendado
A28: 27 | B28: julio 25 | C28: externa | D28: Fernanda Rojas | E28: Patricio Araya Tapia | F28: Externo | G28: Profesional B C | H28: Prevencionista de Riesgos | I28: AM Melinka | J28: Producción AM | K28: Sí | L28: A170040211 | M28: CV_Patricio_Araya.pdf | N28: DC_Prevencionista_de_Riesgos.pdf | O28: Indagar en capacidad analítica y manejo de herramientas digitales. | P28: 2 referencias favorables | Q28: 45855 | R28: 45861 | S28: 45862 | T28: =NETWORKDAYS(R28,S28)-1 | U28: Recomendado con observaciones
A29: 28 | B29: julio 25 | C29: interna | D29: Javiera Soto | E29: Francisco Gutiérrez Hernández | F29: Interno | G29: Profesional A | H29: Jefe de Proyectos TI | I29: Oficina Central | J29: Corporativo | K29: No | N29: DC_Jefe_de_Proyectos_TI.pdf | O29: Énfasis en visión estratégica y relacionamiento con gerencias. | Q29: 45847 | R29: 45853 | S29: 45859 | T29: =NETWORKDAYS(R29,S29)-1 | U29: Recomendado
A30: 29 | B30: julio 25 | C30: interna | D30: Macarena Vidal | E30: Andrés Valenzuela López | F30: Interno | G30: Supervisor B | H30: Supervisor Planta | I30: Planta Cailin | J30: Industrial | K30: No | L30: A170021507 | N30: DC_Supervisor_Planta.pdf | O30: Énfasis en comunicación efectiva y toma de decisiones bajo presión. | Q30: 45845 | R30: 45852 | S30: 45853 | T30: =NETWORKDAYS(R30,S30)-1 | U30: No recomendado
A31: 30 | B31: julio 25 | C31: externa | D31: Javiera Soto | E31: Karen Martínez Contreras | F31: Externo | G31: Profesional A | H31: Jefe de Proyectos TI | I31: Oficina Central | J31: Corporativo | K31: Sí | L31: A170010301 | M31: CV_Karen_Martínez.pdf | N31: DC_Jefe_de_Proyectos_TI.pdf | O31: Indagar en liderazgo de equipos y gestión del cambio. Proceso confidencial para el candidato. | P31: 1 referencia con observaciones | Q31: 45856 | R31: 45861 | S31: 45867 | T31: =NETWORKDAYS(R31,S31)-1 | U31: Recomendado con observaciones
A32: 31 | B32: julio 25 | C32: interna | D32: Carolina Muñoz | E32: Felipe Vargas Contreras | F32: Interno | G32: Técnico A | H32: Técnico Mantención Senior | I32: AM Chonchi | J32: Producción AM | K32: No | L32: A170040512 | N32: DC_Técnico_Mantención_Senior.pdf | O32: Indagar en resolución de problemas técnicos y autonomía. | Q32: 45852 | R32: 45856 | S32: 45861 | T32: =NETWORKDAYS(R32,S32)-1 | U32: Recomendado
A33: 32 | B33: julio 25 | C33: interna | D33: Daniela Contreras | E33: Andrea Castro López | F33: Interno | G33: Profesional B C | H33: Prevencionista de Riesgos | I33: Pargua PA | J33: Otros Producción | K33: No | N33: DC_Prevencionista_de_Riesgos.pdf | O33: Indagar en capacidad analítica y manejo de herramientas digitales. | Q33: 45859 | R33: 45861 | S33: 45867 | T33: =NETWORKDAYS(R33,S33)-1 | U33: Recomendado
A34: 33 | B34: julio 25 | C34: interna | D34: Javiera Soto | E34: Paulina Ruiz Sepúlveda | F34: Interno | G34: Técnico B C | H34: Técnico Laboratorio | I34: Codihue | J34: Producción AD | K34: No | L34: A170050102 | N34: DC_Técnico_Laboratorio.pdf | O34: Indagar en disposición a turnos rotativos. | Q34: 45855 | R34: 45859 | S34: 45863 | T34: =NETWORKDAYS(R34,S34)-1 | U34: Recomendado
A35: 34 | B35: agosto 25 | C35: interna | D35: Carolina Muñoz | E35: Paola Castillo Cárcamo | F35: Interno | G35: Operario Calificado | H35: Grúero | I35: Planta Magallanes | J35: Industrial | K35: No | L35: A170020712 | N35: DC_Grúero.pdf | O35: Validar autocuidado y cumplimiento de procedimientos. | Q35: 45873 | R35: 45880 | S35: 45882 | T35: =NETWORKDAYS(R35,S35)-1 | U35: Recomendado
A36: 35 | B36: agosto 25 | C36: externa | D36: Javiera Soto | E36: Nicolás Oyarzún Gallardo | F36: Externo | G36: Supervisor B | H36: Supervisor Centro de Cultivo | I36: AM Chonchi | J36: Producción AM | K36: Sí | L36: A170040506 | M36: CV_Nicolás_Oyarzún.pdf | N36: DC_Supervisor_Centro_de_Cultivo.pdf | O36: Énfasis en comunicación efectiva y toma de decisiones bajo presión. | P36: Referencias favorables | Q36: 45873 | R36: 45875 | S36: 45881 | T36: =NETWORKDAYS(R36,S36)-1 | U36: No recomendado
A37: 36 | B37: agosto 25 | C37: interna | D37: Javiera Soto | E37: Sebastián Castillo Cárcamo | F37: Interno | G37: Operario Calificado | H37: Operador Grúa Horquilla | I37: Planta Cailin | J37: Industrial | K37: No | N37: DC_Operador_Grúa_Horquilla.pdf | O37: Validar autocuidado y cumplimiento de procedimientos. | Q37: 45875 | R37: 45880 | S37: 45884 | T37: =NETWORKDAYS(R37,S37)-1 | U37: Recomendado
A38: 37 | B38: agosto 25 | C38: externa | D38: Daniela Contreras | E38: Andrés Martínez Vásquez | F38: Externo | G38: Técnico A | H38: Técnico Eléctrico | I38: Pargua PA | J38: Otros Producción | K38: No | L38: A170030405 | M38: CV_Andrés_Martínez.pdf | N38: DC_Técnico_Eléctrico.pdf | O38: Énfasis en disposición a sistema de turnos 7x7 en centro remoto. | Q38: 45880 | R38: 45882 | S38: 45884 | T38: =NETWORKDAYS(R38,S38)-1 | U38: Recomendado
A39: 38 | B39: agosto 25 | C39: externa | D39: Macarena Vidal | E39: Claudio Silva Flores | F39: Externo | G39: Profesional B C | H39: Analista de Control de Gestión | I39: Oficina Central | J39: Corporativo | K39: Sí | L39: A170010305 | M39: CV_Claudio_Silva.pdf | N39: DC_Analista_de_Control_de_Gestión.pdf | O39: Validar tolerancia a la presión y organización de tareas. | P39: 2 referencias favorables | Q39: 45888 | R39: 45895 | S39: 45898 | T39: =NETWORKDAYS(R39,S39)-1 | U39: Recomendado
A40: 39 | B40: agosto 25 | C40: interna | D40: Fernanda Rojas | E40: Víctor Ruiz Mansilla | F40: Interno | G40: Técnico B C | H40: Monitor Producción | I40: Planta Magallanes | J40: Industrial | K40: No | L40: A170020706 | N40: DC_Monitor_Producción.pdf | O40: Énfasis en trabajo en equipo y rigurosidad. | Q40: 45890 | R40: 45896 | S40: 45897 | T40: =NETWORKDAYS(R40,S40)-1 | U40: No recomendado
...

Sheet Resumen
A1: Resumen evaluaciones psicolaborales (datos simulados, abr-2025 a mar-2026)
A3: Categoría | B3: Cantidad | C3: %
A4: Recomendado | B4: =COUNTIF(Candidatos!$U$2:$U$101,A4) | C4: =B4/$B$7
A5: Recomendado con observaciones | B5: =COUNTIF(Candidatos!$U$2:$U$101,A5) | C5: =B5/$B$7
A6: No recomendado | B6: =COUNTIF(Candidatos!$U$2:$U$101,A6) | C6: =B6/$B$7
A7: Total | B7: =SUM(B4:B6)
A9: Origen | B9: Cantidad
A10: Interno | B10: =COUNTIF(Candidatos!$F$2:$F$101,A10)
A11: Externo | B11: =COUNTIF(Candidatos!$F$2:$F$101,A11)
A13: Tiempo de respuesta promedio (días hábiles) | B13: =AVERAGE(Candidatos!$T$2:$T$101)
A15: Mes | B15: Evaluaciones
A16: abril 25 | B16: =COUNTIF(Candidatos!$B$2:$B$101,A16)
A17: mayo 25 | B17: =COUNTIF(Candidatos!$B$2:$B$101,A17)
A18: junio 25 | B18: =COUNTIF(Candidatos!$B$2:$B$101,A18)
A19: julio 25 | B19: =COUNTIF(Candidatos!$B$2:$B$101,A19)
A20: agosto 25 | B20: =COUNTIF(Candidatos!$B$2:$B$101,A20)
A21: septiembre 25 | B21: =COUNTIF(Candidatos!$B$2:$B$101,A21)
A22: octubre 25 | B22: =COUNTIF(Candidatos!$B$2:$B$101,A22)
A23: noviembre 25 | B23: =COUNTIF(Candidatos!$B$2:$B$101,A23)
A24: diciembre 25 | B24: =COUNTIF(Candidatos!$B$2:$B$101,A24)
A25: enero 26 | B25: =COUNTIF(Candidatos!$B$2:$B$101,A25)
A26: febrero 26 | B26: =COUNTIF(Candidatos!$B$2:$B$101,A26)
A27: marzo 26 | B27: =COUNTIF(Candidatos!$B$2:$B$101,A27)
A29: Nota: todos los nombres, reclutadores, CECO y fechas son ficticios, generados para el MVP (DSY1104).
